<?xml version="1.0"?>

<robot name="rw_bot" xmlns:xacro="http://www.ros.org/wiki/xacro">

    <xacro:property name="PI" value="3.14159265"/>
    <xacro:property name="wheel_radius" value="0.113"/> <!-- From DiffDrive plugin -->
    <xacro:property name="wheel_separation" value="0.554"/> <!-- From DiffDrive plugin -->

    <!-- MATERIALS -->
    <material name="white"> <color rgba="1 1 1 1"/> </material>
    <material name="gray"> <color rgba="0.7529 0.7529 0.7529 1"/> </material>
    <material name="blue"> <color rgba="0.2 0.2 1 1"/> </material>
    <material name="black"> <color rgba="0 0 0 1"/> </material>
    <material name="red"> <color rgba="1 0 0 1"/> </material>

    <!-- Robot footprint -->
    <link name="base_footprint"></link>

    <!-- Body Link -->
    <joint name="base_footprint_joint" type="fixed">
        <origin xyz="0 0 0" rpy="0 0 0" />
        <parent link="base_footprint"/>
        <child link="base_link" />
    </joint>

    <link name="base_link">
        <visual>
            <origin xyz="0.0 0.0 0.0" rpy="0.0 0.0 0.0"/>
            <geometry>
                <mesh filename="file://$(find rw)/robot_meshes/base_link.dae" />
            </geometry>
            <material name="gray"/>
        </visual>

        <collision>
            <origin xyz="0.0 0.0 0.0" rpy="0.0 0.0 0.0"/>
            <geometry>
                <mesh filename="file://$(find rw)/robot_meshes/base_link.dae" />
            </geometry>
        </collision>

        <inertial>
            <mass value="108.1344"/>
            <origin xyz="0.4 0.0 0.1" rpy="0 0 0"/>
            <inertia ixx="10.676941" ixy="1.091112" ixz="4.978444"
                     iyy="13.959391" iyz="-1.583958"
                     izz="9.277521"/>
        </inertial>
    </link>
    <gazebo reference="base_link"> <mu1>1.0</mu1> <mu2>1.0</mu2> </gazebo>      

    <!-- Left Wheel -->
    <link name="wheel_left_link">
        <visual>
            <origin xyz="0.0 0.0 0.0" rpy="0.0 0.0 0.0"/>
            <geometry>
                <mesh filename="file://$(find rw)/robot_meshes/left_wheel.dae" />
            </geometry>
            <material name="black"/>
        </visual>
        <collision>
            <origin xyz="0.0 0.0 0.0" rpy="0.0 0.0 0.0"/>
            <geometry>
                <mesh filename="file://$(find rw)/robot_meshes/left_wheel.dae" />
            </geometry>
        </collision>
        <inertial>
            <mass value="0.54077"/>
            <origin xyz="0.0 -0.025 0.0" rpy="0.0 0.0 0.0"/>
            <inertia ixx="0.0033" ixy="0.0" ixz="0.0" 
                     iyy="0.0055" iyz="0.0" 
                     izz="0.0033"/>
        </inertial>
    </link>

    <joint name="wheel_left_joint" type="continuous">
        <origin xyz="0.0 ${-wheel_separation/2} 0" rpy="0 0 0" />
        <parent link="base_link"/>
        <child link="wheel_left_link"/>
        <axis xyz="0 1 0"/>
        <limit effort="50" velocity="10"/>
        <dynamics damping="0.1" friction="0.1"/>
    </joint>
    <gazebo reference="wheel_right_link"> <mu1>1.0</mu1> <mu2>1.0</mu2> <material>Gazebo/Black</material> </gazebo>

    <!-- right Wheel -->
    <link name="wheel_right_link">
        <visual>
            <origin xyz="0.0 0.0 0.0" rpy="0.0 0.0 0.0"/>
            <geometry>
                <mesh filename="file://$(find rw)/robot_meshes/right_wheel.dae" />
            </geometry>
            <material name="black"/>
        </visual>
        <collision>
            <origin xyz="0.0 0.0 0.0" rpy="0.0 0.0 0.0"/>
            <geometry>
                <mesh filename="file://$(find rw)/robot_meshes/right_wheel.dae" />
            </geometry>
        </collision>
        <inertial>
            <mass value="0.54077"/>
            <origin xyz="0.0 0.025 0.0" rpy="0.0 0.0 0.0"/>
            <inertia ixx="0.0033" ixy="0.0" ixz="0.0" 
                     iyy="0.0055" iyz="0.0" 
                     izz="0.0033"/>
        </inertial>
    </link>

    <joint name="wheel_right_joint" type="continuous">
        <origin xyz="0.0 ${wheel_separation/2} 0" rpy="0 0 0" />
        <parent link="base_link"/>
        <child link="wheel_right_link"/>
        <axis xyz="0 1 0"/>
        <limit effort="50" velocity="10"/>
        <dynamics damping="0.1" friction="0.1"/>
    </joint>
    <gazebo reference="wheel_right_link"> <mu1>1.0</mu1> <mu2>1.0</mu2> <material>Gazebo/Black</material> </gazebo>

    <!-- FRONT LEFT CASTER WHEEL LINK -->
    <link name="front_left_caster_wheel_link">
        <visual>
            <origin xyz="0.0 0.0 0.0" rpy="0.0 0.0 0.0"/>
            <geometry>
                <mesh filename="file://$(find rw)/robot_meshes/left_casterWheel.dae" />
            </geometry>
            <material name="black"/>
        </visual>
        <collision>
            <origin xyz="0.0 0.0 0.0" rpy="0.0 0.0 0.0"/>
            <geometry>
                <sphere radius="0.11"/>
            </geometry>
        </collision>
        <inertial>
            <mass value="0.3064"/>
            <origin xyz="-0.018414 -0.00073 -0.044153" rpy="0.0 0.0 0.0"/>
            <!-- Inertia estimated via scaling Aluminum results -->
            <inertia ixx="0.000354" ixy="0.0" ixz="-0.000042"
                     iyy="0.000475" iyz="0.0"
                     izz="0.000210"/>
        </inertial>
    </link>

    <joint name="front_left_caster_wheel_joint" type="fixed">
        <origin xyz="0.6490525 0.2152957 -0.0024993" rpy="0 0 0"/>
        <parent link="base_link"/>
        <child link="front_left_caster_wheel_link"/>
        <dynamics damping="0.1" friction="0.1"/>
    </joint>

    <gazebo reference="front_left_caster_wheel_link">
        <mu1>0.0</mu1>
        <mu2>0.1</mu2>
    </gazebo>

    <!-- FRONT RIGHT CASTER WHEEL -->
    <link name="front_right_caster_wheel_link">
        <visual>
            <origin xyz="0.0 0.0 0.0" rpy="0.0 0.0 0.0"/>
            <geometry>
                <mesh filename="file://$(find rw)/robot_meshes/right_casterWheel.dae" />
            </geometry>
            <material name="black"/>
        </visual>
        <collision>
            <origin xyz="0.0 0.0 0.0" rpy="0.0 0.0 0.0"/>
            <geometry>
                 <sphere radius="0.11"/>
            </geometry>
            <material name="black"/>
        </collision>
        <inertial>
            <mass value="0.3064"/>
            <origin xyz="-0.018414 0.00073 -0.044153" rpy="0.0 0.0 0.0"/>
            <!-- Inertia estimated via scaling Aluminum results -->
            <inertia ixx="0.000354" ixy="0.0" ixz="-0.000042"
                     iyy="0.000475" iyz="0.0"
                     izz="0.000210"/>
        </inertial>
    </link>

    <joint name="front_right_caster_wheel_joint" type="fixed">
        <origin xyz="0.6490525 -0.2152957 -0.0024993" rpy="0 0 0"/>
        <parent link="base_link"/>
        <child link="front_right_caster_wheel_link"/>
        <dynamics damping="0.1" friction="0.1"/>
    </joint>

    <gazebo reference="front_right_caster_wheel_link">
        <mu1>0.1</mu1>
        <mu2>0.1</mu2>
    </gazebo>

    <!-- Back CAMERA -->
    <link name="back_camera_link">
        <visual>
            <geometry>
                <mesh filename="file://$(find rw)/robot_meshes/back_camera.dae" />
            </geometry>
            <material name="blue"/>
        </visual>
        <collision>
            <origin xyz="0.0 0.0 0.0" rpy="0.0 0.0 0.0"/>
            <geometry>
                <mesh filename="file://$(find rw)/robot_meshes/back_camera.dae" />
            </geometry>
            <material name="blue"/>
        </collision>
    </link>

    <joint name="back_camera_joint" type="fixed">
        <parent link="base_link"/>
        <child link="back_camera_link"/>
        <origin xyz="-0.0431295 0 0.1042074" rpy="0 0 0"/>
    </joint>

    <link name="back_camera_link_optical"></link>

    <joint name="back_camera_optical_joint" type="fixed">
        <parent link="back_camera_link"/>
        <child link="back_camera_link_optical"/>
        <origin xyz="-0.0621685 0 -0.0048553" rpy="0 ${3*pi/4} 0"/>
    </joint>

    <gazebo reference="back_camera_link_optical">
        <sensor name="rgbd_camera" type="rgbd_camera">
        <camera>
            <horizontal_fov>1.9</horizontal_fov>
            <image>
            <width>640</width>
            <height>640</height>
            </image>
            <clip>
            <near>0.001</near>
            <far>1</far>
            </clip>
            <optical_frame_id>back_camera_link_optical</optical_frame_id>
        </camera>
        <always_on>1</always_on>
        <update_rate>20</update_rate>
        <visualize>true</visualize>
        <topic>camera2</topic>
        <gz_frame_id>back_camera_link</gz_frame_id>
        </sensor>
    </gazebo>

    <!-- Pan and tile kit -->
    <link name="panAndTile_kit">
        <visual>
            <origin xyz="0.0 0.0 0.0" rpy="0.0 0.0 0.0"/>
            <geometry>
                <mesh filename="file://$(find rw)/robot_meshes/panAndTile_kit.dae" />
            </geometry>
            <material name="red"/>
        </visual>
        <collision>
            <origin xyz="0.0 0.0 0.0" rpy="0.0 0.0 0.0"/>
            <geometry>
                <mesh filename="file://$(find rw)/robot_meshes/panAndTile_kit.dae" />
            </geometry>
            <material name="red"/>
        </collision>
        <inertial>
            <mass value="2"/>
            <inertia ixx="0.1" ixy="0.0" ixz="0.0" iyy="0.1" iyz="0.0" izz="0.2"/>
            <origin xyz="0.0 0.0 0.0" rpy="0.0 0.0 0.0"/>
        </inertial>
    </link>

    <joint name="panAndTile_kit_joint" type="continuous">
        <origin xyz="0.6622757 0.0 0.7159456" rpy="0 0 0" />
        <parent link="base_link"/>
        <child link="panAndTile_kit"/>
        <axis xyz="0 0 1"/>
        <limit effort="100" velocity="300.0"/>
        <dynamics damping="1" friction="1"/>
    </joint>

    <gazebo reference="panAndTile_kit">
        <mu1>1.0</mu1>
        <mu2>1.0</mu2>
    </gazebo>

    <!-- front CAMERA -->
    <link name="front_camera_link">
        <visual>
            <geometry>
                <mesh filename="file://$(find rw)/robot_meshes/front_camera.dae" />
            </geometry>
            <material name="blue"/>
        </visual>
        <collision>
            <origin xyz="0.0 0.0 0.0" rpy="0.0 0.0 0.0"/>
            <geometry>
                <mesh filename="file://$(find rw)/robot_meshes/front_camera.dae" />
            </geometry>
            <material name="blue"/>
        </collision>
    </link>

    <joint name="front_camera_joint" type="fixed">
        <parent link="panAndTile_kit"/>
        <child link="front_camera_link"/>
        <origin xyz="0.0 0.0 0.01" rpy="0 0 0"/>
    </joint>

    <link name="front_camera_link_optical"></link>

    <joint name="front_camera_optical_joint" type="fixed">
        <parent link="front_camera_link"/>
        <child link="front_camera_link_optical"/>
        <origin xyz="0.0202968 0 0.0228071" rpy="0 -${pi} -${pi}"/>
    </joint>

    <gazebo reference="front_camera_link_optical">
        <sensor name="rgbd_camera" type="rgbd_camera">
        <camera>
            <horizontal_fov>1.25</horizontal_fov>
            <image>
            <width>640</width>
            <height>480</height>
            </image>
            <clip>
            <near>0.3</near>
            <far>15</far>
            </clip>
            <optical_frame_id>front_camera_link_optical</optical_frame_id>
        </camera>
        <always_on>1</always_on>
        <update_rate>20</update_rate>
        <visualize>true</visualize>
        <topic>camera</topic>
        <gz_frame_id>front_camera_link</gz_frame_id>
        </sensor>
    </gazebo>

    <!-- LIDAR -->
    <link name="laser_frame">
        <visual>
            <geometry>
                <mesh filename="file://$(find rw)/robot_meshes/front_lidar.dae" />
            </geometry>
            <material name="white"/>
        </visual>
        <collision>
            <geometry>
                <mesh filename="file://$(find rw)/robot_meshes/front_lidar.dae" />
            </geometry>
            <material name="white"/>
        </collision>
    </link>

    <joint name="laser_joint" type="fixed">
        <parent link="panAndTile_kit"/>
        <child link="laser_frame"/>
        <origin xyz="0.0 0.0 0.0556141" rpy="0 0 0"/>
    </joint>

    <link name="lidar_link_optical"></link>

    <joint name="lidar_optical_joint" type="fixed">
        <parent link="laser_frame"/>
        <child link="lidar_link_optical"/>
        <origin xyz="0.025 0 0.03" rpy="0 -${pi} -${pi}"/>
    </joint>

    <gazebo reference="lidar_link_optical">

        <sensor name="gpu_lidar" type="gpu_lidar">
            <update_rate>30</update_rate>
            <topic>scan</topic>
            <gz_frame_id>lidar_link_optical</gz_frame_id>
            <lidar>
                <scan>
                <horizontal>
                    <samples>50</samples>
                    <!--(max_angle-min_angle)/samples * resolution -->
                    <resolution>1</resolution>
                    <min_angle>${-pi/4}</min_angle>
                    <max_angle>${pi/4}</max_angle>
                </horizontal>
                <!-- Dirty hack for fake lidar detections with ogre 1 rendering in VM -->
                <vertical>
                    <samples>50</samples>
                    <min_angle>${-pi/4}</min_angle>
                    <max_angle>${pi/8}</max_angle>
                </vertical>
                </scan>
                <range>
                <min>0.05</min>
                <max>70</max>
                <resolution>0.01</resolution>
                </range>
                <noise>
                    <type>gaussian</type>
                    <mean>0.0</mean>
                    <stddev>0.01</stddev>
                </noise>
                <frame_id>lidar_link_optical</frame_id>
            </lidar>
            <always_on>1</always_on>
            <visualize>true</visualize>
        </sensor>
    </gazebo>

    <!-- IMU -->
    <joint name="imu_joint" type="fixed">
        <origin xyz="0 0 0" rpy="0 0 0" />
        <parent link="base_link"/>
        <child link="imu_link" />
    </joint>

    <link name="imu_link">
    </link>

    <gazebo reference="imu_link">
        <sensor name="imu" type="imu">
        <always_on>1</always_on>
        <update_rate>50</update_rate>
        <visualize>true</visualize>
        <topic>imu</topic>
        <enable_metrics>true</enable_metrics>
        <gz_frame_id>imu_link</gz_frame_id>
        </sensor>
    </gazebo>

    <!-- GPS -->
    <joint name="navsat_joint" type="fixed">
        <origin xyz="0 0 0" rpy="0 0 0" />
        <parent link="base_link"/>
        <child link="navsat_link" />
    </joint>

    <link name="navsat_link">
    </link>

    <gazebo reference="navsat_link">
        <sensor name="navsat" type="navsat">
        <always_on>1</always_on>
        <update_rate>1</update_rate>
        <topic>navsat</topic>
        <gz_frame_id>navsat_link</gz_frame_id>
        </sensor>
    </gazebo>

    <!-- Gazebo Plugins -->
    <gazebo>
        <plugin filename="gz-sim-diff-drive-system" 
                name="gz::sim::systems::DiffDrive">
            <!-- Input -->
            <topic>cmd_vel</topic>
            <!-- <topic>cmd_vel_tracker</topic> -->

            <!-- Wheel joints -->
            <right_joint>wheel_left_joint</right_joint>
            <left_joint>wheel_right_joint</left_joint>
            <!-- Wheel parameters -->
            <wheel_separation>${wheel_separation}</wheel_separation>
            <wheel_radius>${wheel_radius}</wheel_radius>

            <!-- Control gains and limits -->
            <max_velocity>40.0</max_velocity>
            <max_linear_velocity>2.96</max_linear_velocity>
            <min_linear_velocity>-2.96</min_linear_velocity>
            <max_angular_velocity>10.69</max_angular_velocity>
            <min_angular_velocity>-10.69</min_angular_velocity>
            <max_linear_acceleration>10.0</max_linear_acceleration>
            <min_linear_acceleration>-10.0</min_linear_acceleration>
            <max_angular_acceleration>20.0</max_angular_acceleration>
            <min_angular_acceleration>-20.0</min_angular_acceleration>

            <!-- Output -->
            <odom_topic>odom</odom_topic>                  <!-- Odometry topic -->
            <tf_topic>tf</tf_topic>
            <frame_id>odom</frame_id>
            <child_frame_id>base_footprint</child_frame_id>
            <odom_publish_frequency>50</odom_publish_frequency>
        </plugin>

        <plugin filename="gz-sim-joint-state-publisher-system" 
                name="gz::sim::systems::JointStatePublisher">
            <topic>joint_states</topic>
            <joint_name>wheel_left_joint</joint_name>
            <joint_name>wheel_right_joint</joint_name>
            <joint_name>panAndTile_kit_joint</joint_name>
        </plugin>

    </gazebo>
</robot>
